Workbook

Sheet 서부산낙동강교(김해) P5-1
A1: 세 굴 심 검 토 : | T1: 서부산낙동강교(김해) P5-1
B4: ◆ | C4: 검토조건
D5: EL.0 | H5: 지반 EL | V5: =Data!Q4 -> -7.89
D6: EL.1 | H6: 기초푸팅의 상면 EL | V6: =Data!M4 -> -50.5
D7: EL.2 | H7: 기초푸팅의 저면 EL | V7: =Data!J4 -> -60.9
D8: h | H8: 기초푸팅 높이(m) | V8: =Data!L4 -> 10.4
D9: h1 | H9: 지반~기초상면높이(m) | V9: =V5-V6 -> 42.61
D10: y | H10: 수 심 (m) | V10: =Data!T4 -> 9.75
D11: A | H11: 통수단면적 (m2) | V11: =V12*V10 -> 4933.5
D12: W | H12: 수면폭 (m) | V12: 506
D13: b | H13: 교각의 폭 (m) | V13: 3
D14: b' | H14: 흐름의직각방향에대한투영교각의 폭 (m) | V14: 3
D15: Fr | H15: Froude 수 | V15: =AE15 -> 0.29447991 | AD15: (=v/SQRT(g.y)) | AE15: =V16/SQRT(9.81*V10) -> 0.29447991
D16: V | H16: 접근유속 (m/sec) | V16: =Data!U4 -> 2.88
D17: D50 | H17: 평균입경 (m) | V17: 0.00192
D18: YS | H18: 실제발생 가능한 세굴심 (m) | V18: =V5-V6 -> 42.61 | AD18: 지표면부터 암반까지의 깊이
B21: 1) C . S . U. 공식
G22: ds | H22: = | I22: 2 * k1 * k2 * k3 * k4 | P22: * ( | Q22: b | R22: ) 0.65 * ( Fr ) 0.43
G23: y | Q23: y
H24: k1 | I24: (교각형상에 따른 보정계수) | T24: : | U24: 1
H25: k2 | I25: (흐름입사각에 대한 보정계수) | T25: : | U25: 1
H26: k3 | I26: (하상조건에 대한 보정계수) | T26: : | U26: 1.1
H27: k4 | I27: (하상재료의 크기에 대한 보정계수) | T27: : | U27: 1
E28: ds | G28: = | H28: 2 | I28: * | J28: =U24 -> 1 | K28: * | L28: =U25 -> 1 | M28: * | N28: =U26 -> 1.1 | O28: * | P28: =U27 -> 1 | Q28: * | R28: ( | S28: =V13 -> 3 | U28: ) 0.65 | W28: * ( | Y28: =V15 -> 0.29447991 | AA28: )0.43
E29: =V10 -> 9.75 | S29: =E29 -> 9.75
G30: ds | H30: = | I30: =(E29*H28*J28*L28*N28*P28*((S28/S29)^0.65)*(Y28^0.43)) -> 5.8938225 | K30: m
B32: 2) Neill 공식
H33: ds | I33: = | J33: 1.5 | L33: * | M33: ( | N33: y | O33: )0.3
H34: b | N34: b
H35: ds | J35: = | K35: 1.5 | M35: ( | N35: =V10 -> 9.75 | P35: )0.3
H36: =V13 -> 3 | N36: =V13 -> 3
H37: ds | I37: = | K37: =H36*K35*((N35/N36)^0.3) -> 6.4088119 | M37: m
B39: 3) Laursen 공식
E40: b | G40: = | H40: 5.5 | J40: * | K40: ds | M40: [ ( | N40: ds | S40: + | T40: 1 | U40: )1.7 - | W40: 1 | X40: ]
E41: y | K41: y | N41: 11.5 | P41: * | Q41: y
E42: =V13 -> 3 | G42: = | H42: 5.5 | J42: * | K42: ds | M42: [ ( | N42: ds | S42: + | T42: 1 | U42: )1.7 - | W42: 1 | X42: ] | AD42: =E42/E43 -> 0.30769231 | AE42: =5.5*(AD43/K43)*(((AD43/(N43*Q43))+1)^1.7-1) -> 0.30733718
E43: =V10 -> 9.75 | K43: =V10 -> 9.75 | N43: 11.5 | P43: * | Q43: =V10 -> 9.75 | AD43: 5.94 | AE43: =IF(ABS(AE42-AD42)<0.01,"OK","NG") -> OK
E44: ds | G44: = | H44: =AD43 -> 5.94 | J44: m
B46: 4) Froehlich 공식
D47: ds | F47: = | G47: 0.32 * | I47: f | J47: ( | K47: b' | L47: ) | M47: 0.62 | N47: ( | O47: y | P47: ) | Q47: 0.46 | R47: Fr | S47: 0.2 | T47: ( | U47: b | V47: ) | W47: 0.08 | X47: + | Y47: 1
...

Sheet 서부산낙동강교(김해) P6-2
A1: 세 굴 심 검 토 : | T1: 서부산낙동강교(김해) P6-2
B4: ◆ | C4: 검토조건
D5: EL.0 | H5: 지반 EL | V5: =Data!Q8 -> -10.3
D6: EL.1 | H6: 기초푸팅의 상면 EL | V6: =Data!M8 -> -48
D7: EL.2 | H7: 기초푸팅의 저면 EL | V7: =Data!J8 -> -60.9
D8: h | H8: 기초푸팅 높이(m) | V8: =Data!L8 -> 12.9
D9: h1 | H9: 지반~기초상면높이(m) | V9: =V5-V6 -> 37.7
D10: y | H10: 수 심 (m) | V10: =Data!T8 -> 12.4
D11: A | H11: 통수단면적 (m2) | V11: =V12*V10 -> 6274.4
D12: W | H12: 수면폭 (m) | V12: 506
D13: b | H13: 교각의 폭 (m) | V13: 3
D14: b' | H14: 흐름의직각방향에대한투영교각의 폭 (m) | V14: 3
D15: Fr | H15: Froude 수 | V15: =AE15 -> 0.26112421 | AD15: (=v/SQRT(g.y)) | AE15: =V16/SQRT(9.81*V10) -> 0.26112421
D16: V | H16: 접근유속 (m/sec) | V16: =Data!U8 -> 2.88
D17: D50 | H17: 평균입경 (m) | V17: 0.00192
D18: YS | H18: 실제발생 가능한 세굴심 (m) | V18: =V5-V6 -> 37.7 | AD18: 지표면부터 암반까지의 깊이
B21: 1) C . S . U. 공식
G22: ds | H22: = | I22: 2 * k1 * k2 * k3 * k4 | P22: * ( | Q22: b | R22: ) 0.65 * ( Fr ) 0.43
G23: y | Q23: y
H24: k1 | I24: (교각형상에 따른 보정계수) | T24: : | U24: 1
H25: k2 | I25: (흐름입사각에 대한 보정계수) | T25: : | U25: 1
H26: k3 | I26: (하상조건에 대한 보정계수) | T26: : | U26: 1.1
H27: k4 | I27: (하상재료의 크기에 대한 보정계수) | T27: : | U27: 1
E28: ds | G28: = | H28: 2 | I28: * | J28: =U24 -> 1 | K28: * | L28: =U25 -> 1 | M28: * | N28: =U26 -> 1.1 | O28: * | P28: =U27 -> 1 | Q28: * | R28: ( | S28: =V13 -> 3 | U28: ) 0.65 | W28: * ( | Y28: =V15 -> 0.26112421 | AA28: )0.43
E29: =V10 -> 12.4 | S29: =E29 -> 12.4
G30: ds | H30: = | I30: =(E29*H28*J28*L28*N28*P28*((S28/S29)^0.65)*(Y28^0.43)) -> 6.0882623 | K30: m
B32: 2) Neill 공식
H33: ds | I33: = | J33: 1.5 | L33: * | M33: ( | N33: y | O33: )0.3
H34: b | N34: b
H35: ds | J35: = | K35: 1.5 | M35: ( | N35: =V10 -> 12.4 | P35: )0.3
H36: =V13 -> 3 | N36: =V13 -> 3
H37: ds | I37: = | K37: =H36*K35*((N35/N36)^0.3) -> 6.8881507 | M37: m
B39: 3) Laursen 공식
E40: b | G40: = | H40: 5.5 | J40: * | K40: ds | M40: [ ( | N40: ds | S40: + | T40: 1 | U40: )1.7 - | W40: 1 | X40: ]
E41: y | K41: y | N41: 11.5 | P41: * | Q41: y
E42: =V13 -> 3 | G42: = | H42: 5.5 | J42: * | K42: ds | M42: [ ( | N42: ds | S42: + | T42: 1 | U42: )1.7 - | W42: 1 | X42: ] | AD42: =E42/E43 -> 0.24193548 | AE42: =5.5*(AD43/K43)*(((AD43/(N43*Q43))+1)^1.7-1) -> 0.24197864
E43: =V10 -> 12.4 | K43: =V10 -> 12.4 | N43: 11.5 | P43: * | Q43: =V10 -> 12.4 | AD43: 6.71 | AE43: =IF(ABS(AE42-AD42)<0.01,"OK","NG") -> OK
E44: ds | G44: = | H44: =AD43 -> 6.71 | J44: m
B46: 4) Froehlich 공식
D47: ds | F47: = | G47: 0.32 * | I47: f | J47: ( | K47: b' | L47: ) | M47: 0.62 | N47: ( | O47: y | P47: ) | Q47: 0.46 | R47: Fr | S47: 0.2 | T47: ( | U47: b | V47: ) | W47: 0.08 | X47: + | Y47: 1
...

Sheet 서부산낙동강교(김해) P7-1
A1: 세 굴 심 검 토 : | T1: 서부산낙동강교(김해) P7-1
B4: ◆ | C4: 검토조건
D5: EL.0 | H5: 지반 EL | V5: =Data!Q12 -> -11.19
D6: EL.1 | H6: 기초푸팅의 상면 EL | V6: =Data!M12 -> -46.5
D7: EL.2 | H7: 기초푸팅의 저면 EL | V7: =Data!J12 -> -60.6
D8: h | H8: 기초푸팅 높이(m) | V8: =Data!L12 -> 14.1
D9: h1 | H9: 지반~기초상면높이(m) | V9: =V5-V6 -> 35.31
D10: y | H10: 수 심 (m) | V10: =Data!T12 -> 12
D11: A | H11: 통수단면적 (m2) | V11: =V12*V10 -> 6072
D12: W | H12: 수면폭 (m) | V12: 506
D13: b | H13: 교각의 폭 (m) | V13: 3
D14: b' | H14: 흐름의직각방향에대한투영교각의 폭 (m) | V14: 3
D15: Fr | H15: Froude 수 | V15: =AE15 -> 0.26544061 | AD15: (=v/SQRT(g.y)) | AE15: =V16/SQRT(9.81*V10) -> 0.26544061
D16: V | H16: 접근유속 (m/sec) | V16: =Data!U12 -> 2.88
D17: D50 | H17: 평균입경 (m) | V17: 0.00192
D18: YS | H18: 실제발생 가능한 세굴심 (m) | V18: =V5-V6 -> 35.31 | AD18: 지표면부터 암반까지의 깊이
B21: 1) C . S . U. 공식
G22: ds | H22: = | I22: 2 * k1 * k2 * k3 * k4 | P22: * ( | Q22: b | R22: ) 0.65 * ( Fr ) 0.43
G23: y | Q23: y
H24: k1 | I24: (교각형상에 따른 보정계수) | T24: : | U24: 1
H25: k2 | I25: (흐름입사각에 대한 보정계수) | T25: : | U25: 1
H26: k3 | I26: (하상조건에 대한 보정계수) | T26: : | U26: 1.1
H27: k4 | I27: (하상재료의 크기에 대한 보정계수) | T27: : | U27: 1
E28: ds | G28: = | H28: 2 | I28: * | J28: =U24 -> 1 | K28: * | L28: =U25 -> 1 | M28: * | N28: =U26 -> 1.1 | O28: * | P28: =U27 -> 1 | Q28: * | R28: ( | S28: =V13 -> 3 | U28: ) 0.65 | W28: * ( | Y28: =V15 -> 0.26544061 | AA28: )0.43
E29: =V10 -> 12 | S29: =E29 -> 12
G30: ds | H30: = | I30: =(E29*H28*J28*L28*N28*P28*((S28/S29)^0.65)*(Y28^0.43)) -> 6.0613714 | K30: m
B32: 2) Neill 공식
H33: ds | I33: = | J33: 1.5 | L33: * | M33: ( | N33: y | O33: )0.3
H34: b | N34: b
H35: ds | J35: = | K35: 1.5 | M35: ( | N35: =V10 -> 12 | P35: )0.3
H36: =V13 -> 3 | N36: =V13 -> 3
H37: ds | I37: = | K37: =H36*K35*((N35/N36)^0.3) -> 6.8207245 | M37: m
B39: 3) Laursen 공식
E40: b | G40: = | H40: 5.5 | J40: * | K40: ds | M40: [ ( | N40: ds | S40: + | T40: 1 | U40: )1.7 - | W40: 1 | X40: ]
E41: y | K41: y | N41: 11.5 | P41: * | Q41: y
E42: =V13 -> 3 | G42: = | H42: 5.5 | J42: * | K42: ds | M42: [ ( | N42: ds | S42: + | T42: 1 | U42: )1.7 - | W42: 1 | X42: ] | AD42: =E42/E43 -> 0.25 | AE42: =5.5*(AD43/K43)*(((AD43/(N43*Q43))+1)^1.7-1) -> 0.25004318
E43: =V10 -> 12 | K43: =V10 -> 12 | N43: 11.5 | P43: * | Q43: =V10 -> 12 | AD43: 6.6 | AE43: =IF(ABS(AE42-AD42)<0.01,"OK","NG") -> OK
E44: ds | G44: = | H44: =AD43 -> 6.6 | J44: m
B46: 4) Froehlich 공식
D47: ds | F47: = | G47: 0.32 * | I47: f | J47: ( | K47: b' | L47: ) | M47: 0.62 | N47: ( | O47: y | P47: ) | Q47: 0.46 | R47: Fr | S47: 0.2 | T47: ( | U47: b | V47: ) | W47: 0.08 | X47: + | Y47: 1
...

Sheet 서부산낙동강교(김해) P8-2
A1: 세 굴 심 검 토 : | T1: 서부산낙동강교(김해) P8-2
B4: ◆ | C4: 검토조건
D5: EL.0 | H5: 지반 EL | V5: =Data!Q16 -> -9.89
D6: EL.1 | H6: 기초푸팅의 상면 EL | V6: =Data!M16 -> -46.5
D7: EL.2 | H7: 기초푸팅의 저면 EL | V7: =Data!J16 -> -59.4
D8: h | H8: 기초푸팅 높이(m) | V8: =Data!L16 -> 12.9
D9: h1 | H9: 지반~기초상면높이(m) | V9: =V5-V6 -> 36.61
D10: y | H10: 수 심 (m) | V10: =Data!T16 -> 11
D11: A | H11: 통수단면적 (m2) | V11: =V12*V10 -> 5566
D12: W | H12: 수면폭 (m) | V12: 506
D13: b | H13: 교각의 폭 (m) | V13: 3
D14: b' | H14: 흐름의직각방향에대한투영교각의 폭 (m) | V14: 3
D15: Fr | H15: Froude 수 | V15: =AE15 -> 0.27724367 | AD15: (=v/SQRT(g.y)) | AE15: =V16/SQRT(9.81*V10) -> 0.27724367
D16: V | H16: 접근유속 (m/sec) | V16: =Data!U16 -> 2.88
D17: D50 | H17: 평균입경 (m) | V17: 0.00192
D18: YS | H18: 실제발생 가능한 세굴심 (m) | V18: =V5-V6 -> 36.61 | AD18: 지표면부터 암반까지의 깊이
B21: 1) C . S . U. 공식
G22: ds | H22: = | I22: 2 * k1 * k2 * k3 * k4 | P22: * ( | Q22: b | R22: ) 0.65 * ( Fr ) 0.43
G23: y | Q23: y
H24: k1 | I24: (교각형상에 따른 보정계수) | T24: : | U24: 1
H25: k2 | I25: (흐름입사각에 대한 보정계수) | T25: : | U25: 1
H26: k3 | I26: (하상조건에 대한 보정계수) | T26: : | U26: 1.1
H27: k4 | I27: (하상재료의 크기에 대한 보정계수) | T27: : | U27: 1
E28: ds | G28: = | H28: 2 | I28: * | J28: =U24 -> 1 | K28: * | L28: =U25 -> 1 | M28: * | N28: =U26 -> 1.1 | O28: * | P28: =U27 -> 1 | Q28: * | R28: ( | S28: =V13 -> 3 | U28: ) 0.65 | W28: * ( | Y28: =V15 -> 0.27724367 | AA28: )0.43
E29: =V10 -> 11 | S29: =E29 -> 11
G30: ds | H30: = | I30: =(E29*H28*J28*L28*N28*P28*((S28/S29)^0.65)*(Y28^0.43)) -> 5.9905879 | K30: m
B32: 2) Neill 공식
H33: ds | I33: = | J33: 1.5 | L33: * | M33: ( | N33: y | O33: )0.3
H34: b | N34: b
H35: ds | J35: = | K35: 1.5 | M35: ( | N35: =V10 -> 11 | P35: )0.3
H36: =V13 -> 3 | N36: =V13 -> 3
H37: ds | I37: = | K37: =H36*K35*((N35/N36)^0.3) -> 6.6449841 | M37: m
B39: 3) Laursen 공식
E40: b | G40: = | H40: 5.5 | J40: * | K40: ds | M40: [ ( | N40: ds | S40: + | T40: 1 | U40: )1.7 - | W40: 1 | X40: ]
E41: y | K41: y | N41: 11.5 | P41: * | Q41: y
E42: =V13 -> 3 | G42: = | H42: 5.5 | J42: * | K42: ds | M42: [ ( | N42: ds | S42: + | T42: 1 | U42: )1.7 - | W42: 1 | X42: ] | AD42: =E42/E43 -> 0.27272727 | AE42: =5.5*(AD43/K43)*(((AD43/(N43*Q43))+1)^1.7-1) -> 0.27305766
E43: =V10 -> 11 | K43: =V10 -> 11 | N43: 11.5 | P43: * | Q43: =V10 -> 11 | AD43: 6.32 | AE43: =IF(ABS(AE42-AD42)<0.01,"OK","NG") -> OK
E44: ds | G44: = | H44: =AD43 -> 6.32 | J44: m
B46: 4) Froehlich 공식
D47: ds | F47: = | G47: 0.32 * | I47: f | J47: ( | K47: b' | L47: ) | M47: 0.62 | N47: ( | O47: y | P47: ) | Q47: 0.46 | R47: Fr | S47: 0.2 | T47: ( | U47: b | V47: ) | W47: 0.08 | X47: + | Y47: 1
...

Sheet 서부산낙동강교(김해) P9-1
A1: 세 굴 심 검 토 : | T1: 서부산낙동강교(김해) P9-1
B4: ◆ | C4: 검토조건
D5: EL.0 | H5: 지반 EL | V5: =Data!Q20 -> -4.83
D6: EL.1 | H6: 기초푸팅의 상면 EL | V6: =Data!M20 -> -63.3
D7: EL.2 | H7: 기초푸팅의 저면 EL | V7: =Data!J20 -> -64.9
D8: h | H8: 기초푸팅 높이(m) | V8: =Data!L20 -> 1.6
D9: h1 | H9: 지반~기초상면높이(m) | V9: =V5-V6 -> 58.47
D10: y | H10: 수 심 (m) | V10: =Data!T20 -> 6.2
D11: A | H11: 통수단면적 (m2) | V11: =V12*V10 -> 3137.2
D12: W | H12: 수면폭 (m) | V12: 506
D13: b | H13: 교각의 폭 (m) | V13: 3
D14: b' | H14: 흐름의직각방향에대한투영교각의 폭 (m) | V14: 3
D15: Fr | H15: Froude 수 | V15: =AE15 -> 0.3692854 | AD15: (=v/SQRT(g.y)) | AE15: =V16/SQRT(9.81*V10) -> 0.3692854
D16: V | H16: 접근유속 (m/sec) | V16: =Data!U20 -> 2.88
D17: D50 | H17: 평균입경 (m) | V17: 0.00192
D18: YS | H18: 실제발생 가능한 세굴심 (m) | V18: =V5-V6 -> 58.47 | AD18: 지표면부터 암반까지의 깊이
B21: 1) C . S . U. 공식
G22: ds | H22: = | I22: 2 * k1 * k2 * k3 * k4 | P22: * ( | Q22: b | R22: ) 0.65 * ( Fr ) 0.43
G23: y | Q23: y
H24: k1 | I24: (교각형상에 따른 보정계수) | T24: : | U24: 1
H25: k2 | I25: (흐름입사각에 대한 보정계수) | T25: : | U25: 1
H26: k3 | I26: (하상조건에 대한 보정계수) | T26: : | U26: 1.1
H27: k4 | I27: (하상재료의 크기에 대한 보정계수) | T27: : | U27: 1
E28: ds | G28: = | H28: 2 | I28: * | J28: =U24 -> 1 | K28: * | L28: =U25 -> 1 | M28: * | N28: =U26 -> 1.1 | O28: * | P28: =U27 -> 1 | Q28: * | R28: ( | S28: =V13 -> 3 | U28: ) 0.65 | W28: * ( | Y28: =V15 -> 0.3692854 | AA28: )0.43
E29: =V10 -> 6.2 | S29: =E29 -> 6.2
G30: ds | H30: = | I30: =(E29*H28*J28*L28*N28*P28*((S28/S29)^0.65)*(Y28^0.43)) -> 5.5443968 | K30: m
B32: 2) Neill 공식
H33: ds | I33: = | J33: 1.5 | L33: * | M33: ( | N33: y | O33: )0.3
H34: b | N34: b
H35: ds | J35: = | K35: 1.5 | M35: ( | N35: =V10 -> 6.2 | P35: )0.3
H36: =V13 -> 3 | N36: =V13 -> 3
H37: ds | I37: = | K37: =H36*K35*((N35/N36)^0.3) -> 5.5949169 | M37: m
B39: 3) Laursen 공식
E40: b | G40: = | H40: 5.5 | J40: * | K40: ds | M40: [ ( | N40: ds | S40: + | T40: 1 | U40: )1.7 - | W40: 1 | X40: ]
E41: y | K41: y | N41: 11.5 | P41: * | Q41: y
E42: =V13 -> 3 | G42: = | H42: 5.5 | J42: * | K42: ds | M42: [ ( | N42: ds | S42: + | T42: 1 | U42: )1.7 - | W42: 1 | X42: ] | AD42: =E42/E43 -> 0.48387097 | AE42: =5.5*(AD43/K43)*(((AD43/(N43*Q43))+1)^1.7-1) -> 0.48412462
E43: =V10 -> 6.2 | K43: =V10 -> 6.2 | N43: 11.5 | P43: * | Q43: =V10 -> 6.2 | AD43: 4.73 | AE43: =IF(ABS(AE42-AD42)<0.01,"OK","NG") -> OK
E44: ds | G44: = | H44: =AD43 -> 4.73 | J44: m
B46: 4) Froehlich 공식
D47: ds | F47: = | G47: 0.32 * | I47: f | J47: ( | K47: b' | L47: ) | M47: 0.62 | N47: ( | O47: y | P47: ) | Q47: 0.46 | R47: Fr | S47: 0.2 | T47: ( | U47: b | V47: ) | W47: 0.08 | X47: + | Y47: 1
...

Sheet Data
A1: 교각/ 위치 | C1: 수중조사
C2: 총깊이 | D2: <2013> | F2: <2018> | H2: 세굴상태 | J2: 기초저면 EL. | L2: 교각 Footing높이 (m) | M2: 기초상면 EL. | O2: 기둥높이 (m) | P2: 교각 기둥 상단 EL. | Q2: 지반고 EL. | T2: 수심 (m) | U2: 유속 (m/sec) | V2: 평수위(EL.) | X2: 교각 Footing높이 (m)
D3: 노출깊이 | E3: 잔류깊이 | F3: 노출깊이 | G3: 잔류깊이 | J3: 종평면도 | L3: 종평면도 | M3: 종평면도 | N3: 우물통상세도 | O3: 수중조사 | P3: 교각 일반도 | Q3: 수중조사 | S3: 우물통 상세도 기준 | T3: 수중조사 | U3: 지반조사보고서 | V3: 교각일반도 | X3: 교각일반도
A4: P5-1 | J4: -60.9 | L4: =60.9-50.5 -> 10.4 | M4: -50.5 | O4: 12.88 | P4: 6.603 | Q4: -7.89 | T4: 9.75 | U4: 2.88 | V4: 0.51
A8: P6-2 | J8: -60.9 | L8: =60.9-48 -> 12.9 | M8: -48 | O8: 14.65 | P8: 7.988 | Q8: -10.3 | T8: 12.4 | U8: 2.88 | V8: 0.51
A12: P7-1 | J12: -60.6 | L12: =60.6-46.5 -> 14.1 | M12: -46.5 | O12: 14.45 | P12: 6.869 | Q12: -11.19 | T12: 12 | U12: 2.88 | V12: 0.51
A16: P8-2 | J16: -59.4 | L16: =60.9-48 -> 12.9 | M16: -46.5 | O16: 12.74 | P16: 7.142 | Q16: -9.89 | T16: 11 | U16: 2.88 | V16: 0.51
A20: P9-1 | J20: -64.9 | L20: =64.9-63.3 -> 1.6 | M20: -63.3 | O20: 9.68 | P20: 7.199 | Q20: -4.83 | T20: 6.2 | U20: 2.88 | V20: 0.51
V29: 홍수위 | W29: 8.05 | X29: 지반조사보고서
V30: MWL

Sheet 자료 캡쳐
CA58: P6
N59: P4 | AS59: P5 | DG59: P7
